
try {
	${1}
} catch (\Exception $exception) {
	throw $exception;
	${2}
}
